#VRML_SIM R2023b utf8

EXTERNPROTO "https://raw.githubusercontent.com/cyberbotics/webots/R2023b/projects/appearances/protos/BrushedAluminium.proto"
EXTERNPROTO "https://raw.githubusercontent.com/cyberbotics/webots/R2023b/projects/robots/gctronic/e-puck/protos/E-puck.proto"
EXTERNPROTO "https://raw.githubusercontent.com/cyberbotics/webots/R2023b/projects/objects/floors/protos/RectangleArena.proto"
EXTERNPROTO "https://raw.githubusercontent.com/cyberbotics/webots/R2023b/projects/objects/backgrounds/protos/TexturedBackground.proto"
EXTERNPROTO "https://raw.githubusercontent.com/cyberbotics/webots/R2023b/projects/objects/backgrounds/protos/TexturedBackgroundLight.proto"

WorldInfo {
  coordinateSystem "NUE"
}
Viewpoint {
  orientation -0.6019977990792362 0.6232515519467029 0.49915543961754233 2.2719863804420735
  position 0.08157243385440717 0.4621401628231627 1.843859460232547
}
TexturedBackground {
  texture "factory"
}
TexturedBackgroundLight {
}
DEF area RectangleArena {
  rotation -1 0 0 1.0472
  floorSize 1.016 1.016
  floorTileSize 0.508 0.508
  wallAppearance BrushedAluminium {
    colorOverride 0.4 0.4 0.4
  }
}
DEF epuck E-puck {
  hidden position_0_0 -3.964226798610644e-12
  hidden position_0_1 3.9762009363510075e-12
  hidden linearVelocity_0 0.0016251915017069672 -215.57806571724646 1186.7548715653093
  hidden angularVelocity_0 2.0880185022345525 -0.0979278064420849 -0.19151124909358833
  hidden translation_1 0 0.026 0.02
  hidden linearVelocity_1 0.0050990509348784515 -215.60220057866061 1186.80531660246
  hidden angularVelocity_1 2.08801850223091 -0.09792780648360525 -0.1915112490995499
  hidden translation_2 0 -0.026 0.02
  hidden linearVelocity_2 -0.003288465617220951 -215.57417934829553 1186.6991032851006
  hidden angularVelocity_2 2.088018502238254 -0.09792780640619446 -0.19151124908417688
  hidden linearVelocity_45 -0.006006429133678112 -215.61100039945055 1186.688336227308
  hidden angularVelocity_45 2.0880184855697985 -0.09792780568639471 -0.19151124507905593
  hidden linearVelocity_46 -0.005227561602099763 -215.61580208193618 1186.69932031037
  hidden angularVelocity_46 2.088018502259394 -0.09792780645392311 -0.1915112491111418
  translation 0.2522012044133851 21023.27071946797 109044.48541054431
  rotation 0.7786727264261012 0.6000563006857231 -0.18330635866632455 0.38099544869877905
  controller "motionEstimation"
  supervisor TRUE
  camera_width 50
  turretSlot [
    InertialUnit {
      rotation 0 1 0 3.14
    }
    DEF righthinge HingeJoint {
      jointParameters HingeJointParameters {
        position 3.981067092681741e-10
        axis -1 0 0
        anchor 0 0.025 0
      }
      device [
        RotationalMotor {
          name "right wheel motor"
          consumptionFactor 70
          controlPID 8 2 0.5
        }
        PositionSensor {
          name "right wheel sensor"
        }
      ]
      endPoint Solid {
        translation 0.04500995778380096 0.025013380758873813 -2.4671929857397144e-05
        rotation 0.9999993203499806 0.0010052734267047422 -0.0005905293509436107 4.636837121656562
        children [
          DEF WHEEL Pose {
            translation -0.007 0.01 -0.05
            rotation 0 0 1 1.57
            children [
              Shape {
                appearance PBRAppearance {
                  baseColor 0 0 0
                  transparency 1
                  roughness 1
                  metalness 0
                }
                geometry Cylinder {
                  height 0.01
                  radius 0.02
                }
              }
            ]
            rotationStep 0.25
          }
        ]
        name "right wheel(1)"
        boundingObject USE WHEEL
        physics DEF PHYSICS_WHEEL Physics {
          density -1
          mass 0.05
        }
        rotationStep 0.25
      }
    }
    DEF lefthinge HingeJoint {
      jointParameters HingeJointParameters {
        position 2.290600374216901e-10
        axis -1 0 0
        anchor 0 0.025 0
      }
      device [
        RotationalMotor {
          name "left wheel motor"
          consumptionFactor 70
          controlPID 8 0 0
        }
        PositionSensor {
          name "left wheel sensor"
        }
      ]
      endPoint Solid {
        translation -0.04501012942703836 0.024977671977268592 -4.5733976156920565e-05
        rotation -0.9999982113395174 0.000472752685851952 -0.0018313444962472713 1.242581020518019
        children [
          DEF WHEEL Pose {
            translation 0.007 0 -0.05
            rotation 0 0 1 1.57
            children [
              Shape {
                appearance PBRAppearance {
                  baseColor 0.1 0.1 0.1
                  transparency 1
                  roughness 1
                  metalness 0
                }
                geometry Cylinder {
                  height 0.01
                  radius 0.02
                }
              }
            ]
            rotationStep 0.25
          }
        ]
        name "left wheel(1)"
        boundingObject USE WHEEL
        physics DEF PHYSICS_WHEEL Physics {
          density -1
          mass 0.05
        }
      }
    }
    DEF front_ds DistanceSensor {
      translation 0 0 -0.045
      rotation 0 1 0 1.5708
      name "front_ds"
      recognitionColors [
        0 0 0
      ]
      lookupTable [
        0 0 0
        1.27 1.27 0
      ]
    }
    DEF right_ds DistanceSensor {
      translation 0.035 -0.01 -0.01
      name "right_ds"
      lookupTable [
        0 0 0
        1.27 1.27 0
      ]
    }
    DEF left_ds DistanceSensor {
      translation -0.035 -0.01 -0.01
      rotation 0 1 0 3.14159
      name "left_ds"
      lookupTable [
        0 0 0
        1.27 1.27 0
      ]
    }
    Camera {
      translation 0 -0.01 -0.045
      name "camera1"
      recognitionColors [
        1 1 0
      ]
      fieldOfView 1.57
      width 80
      height 80
      recognition Recognition {
      }
    }
  ]
}
